2024-01-24 16:02:30,651 DEBUG connectionpool _new_conn Starting new HTTPS connection (1): archivesspace.library.yale.edu:443
2024-01-24 16:02:31,167 DEBUG connectionpool _make_request https://archivesspace.library.yale.edu:443 "POST /api/users/amd243/login?password=[REDACTED] HTTP/1.1" 200 None
2024-01-24 16:02:31,455 DEBUG connectionpool _make_request https://archivesspace.library.yale.edu:443 "GET /api/repositories/2/resources/13201 HTTP/1.1" 200 None
2024-01-24 16:02:31,996 DEBUG connectionpool _make_request https://archivesspace.library.yale.edu:443 "POST /api/repositories/2/resources/13201/transfer?target_repo=/repositories/3 HTTP/1.1" 400 216
2024-01-24 16:02:31,997 ERROR transfer_resources main ArchivesSpace Error! URI: /repositories/2/resources/13201/transfer?target_repo=/repositories/3, Status code: 400, Message: {'db_error': ['Database integrity constraint conflict: Java::JavaSql::SQLIntegrityConstraintViolationException: Duplicate entry \'3-["0000",null,null,null]\' for key \'resource.resource_unique_identifier\'']}
2024-01-24 16:02:51,063 DEBUG transfer_resources main Skipping record...
2024-01-24 16:02:51,278 DEBUG connectionpool _make_request https://archivesspace.library.yale.edu:443 "GET /api/repositories/2/resources/11734 HTTP/1.1" 200 None
2024-01-24 16:07:51,417 DEBUG connectionpool _make_request https://archivesspace.library.yale.edu:443 "POST /api/repositories/2/resources/11734/transfer?target_repo=/repositories/3 HTTP/1.1" 504 160
2024-01-24 16:07:51,419 ERROR transfer_resources main Expecting value: line 1 column 1 (char 0)
Traceback (most recent call last):
  File "transfer_resources.py", line 296, in main
    row = post_record(api_url, uri, sesh, row)
  File "transfer_resources.py", line 262, in post_record
    raise ArchivesSpaceError(uri, record.status_code, json.loads(record.text))
  File "/Users/aliciadetelich/opt/miniconda3/lib/python3.8/json/__init__.py", line 357, in loads
    return _default_decoder.decode(s)
  File "/Users/aliciadetelich/opt/miniconda3/lib/python3.8/json/decoder.py", line 337, in decode
    obj, end = self.raw_decode(s, idx=_w(s, 0).end())
  File "/Users/aliciadetelich/opt/miniconda3/lib/python3.8/json/decoder.py", line 355, in raw_decode
    raise JSONDecodeError("Expecting value", s, err.value) from None
json.decoder.JSONDecodeError: Expecting value: line 1 column 1 (char 0)
2024-01-24 16:10:33,611 DEBUG connectionpool _new_conn Starting new HTTPS connection (1): archivesspace.library.yale.edu:443
2024-01-24 16:10:34,137 DEBUG connectionpool _make_request https://archivesspace.library.yale.edu:443 "POST /api/users/amd243/login?password=[REDACTED] HTTP/1.1" 200 None
2024-01-24 16:10:34,458 DEBUG connectionpool _make_request https://archivesspace.library.yale.edu:443 "GET /api/repositories/2/resources/13201 HTTP/1.1" 200 None
2024-01-24 16:10:35,010 DEBUG connectionpool _make_request https://archivesspace.library.yale.edu:443 "POST /api/repositories/2/resources/13201/transfer?target_repo=/repositories/3 HTTP/1.1" 400 216
2024-01-24 16:10:46,468 DEBUG transfer_resources main Exiting on user request...
